Workbook
Name Business: BaseData!$G$2:$G$6
Name CustomerExtern: BaseData!$H$2:$H$49
Name Customers: BaseData!$B$2:$B$69
Name Duparec: Depot!$C$2:$C$13
Name HRAdria: Depot!$D$2:$D$13
Name HRBulgaria: Depot!$E$2:$E$13
Name HRCZ: Depot!$M$2:$M$13
Name HREns: Depot!$F$2:$F$13
Name HRGroup: Depot!$G$2:$G$13
Name HRNZ: Depot!$H$2:$H$13
Name HRPolska: Depot!$I$2:$I$13
Name HRRomania: Depot!$J$2:$J$13
Name HRTurkey: Depot!$K$2:$K$13
Name MA200_: DropDownLists!$L$2:$L$101
Name MA210_: DropDownLists!$M$2:$M$101
Name MA215_: DropDownLists!$N$2:$N$101
Name MA230_: DropDownLists!$O$2:$O$101
Name MA240_: DropDownLists!$P$2:$P$101
Name MA250_: DropDownLists!$Q$2:$Q$101
Name MA260_: DropDownLists!$R$2:$R$101
Name MA300_: DropDownLists!$S$2
Name NewCompany: Depot!$B$2:$B$13
Name SCHOzon: Depot!$L$2:$L$13
Name Source: BaseData!$F$2:$F$252
Name Supplier: BaseData!$I$2:$I$119
Name TehnopapirBG: Depot!$N$2:$N$13
Name TehnopapirZV: Depot!$O$2:$O$13

Sheet START
B2: Investment form
B4: =IF(C6="","1. Please select the company!","Selected company:") -> Selected company: | G4: Legend/ color guide
C6: 1661 HR Turkey | E6: =VLOOKUP(C6,Depot!$R$2:$S$30,2,0) -> HRTurkey | H6: field with calculated data - no entry!
B8: =IF(C10="","2. Please select the location!","Selected location:") -> Selected location: | H8: field with drop down selection
C10: 166101 Bornova | H10: field for manual data input
B12: =IF(C14="","2. Please select the actual year!","Selected year:") -> Selected year: | H12: field with calculated data from Sales Report - no entry!
C14: 2021 | H14: field to be filled in by Holding
B16: =IF(OR(C18="",E18=""),"4. Please select the local currency and define the exchange rate!","Selected local currency and exchange rate:") -> Selected local currency and exchange rate:
C18: TRY | D18: 1,00 EUR = | E18: 7.5 | F18: =IF(C18="","","(Proposal from Budget 2019 FX rates: "&ROUND(VLOOKUP(START!C18,FXRates2019!$C$10:$D$50,2,0),5)&")") -> (Proposal from Budget 2019 FX rates: 9,67)
C21: The company calculation shall contain
C22: INFOR data | E22: OR | F22: INFOR data | H22: PLUS | I22: Business plan location | K22: RESULTS IN | L22: Business plan company
C23: from Prev year | F23: from FC
C24: 190100 Sveta Helena | F24: 190100 Sveta Helena | L24: 190100 Sveta Helena
F25: 190101 Split | L25: 190101 Split
F26: 190102 Osijek | L26: 190102 Osijek
I27: 190103 Zagreb | L27: 190103 Zagreb
B37: General guide line: Enter P&L values according to INFOR logic:
B38: Revenue values are positive, expense values are negative!
B39: Please consider the investment information below.
B41: INFOR Input
B43: INFOR-PreviousYearEURO
B44: INFOR OneGroup BI PROD - Recycling Actual:
B47: Open the Report "ACT Rep - P&L All Depots"
B48: Select your profit center and the previous year
B49: and Month: "12 YTD", "in thousands" and "Euro"
B74: Open the Report in Excel and copy in following way:
B75: Press "CTRL" and "pos1" (will mark the cell C2)
B76: Hold "Shift" + "CTRL" and press "End" (will mark relevant area)
... B145: business.
C147: A1 Stabilizing or Replacement Investments with positive return
C148: Investments for replacements with additional benefits, e.g. cost saving – stabilizing in the meaning of “modernization”.
C150: A2 Stabilizing or Replacement Investments with no return
C151: e.g. investments and replacements of existing assets, all company cars, investments in office rooms, social rooms, etc.
C153: A3 Investments for Safety, Health, Environmental or other aspects
C154: Legal requirements independent from positive or no return. Investments which secure legal compliance (e.g. fire protection),
C155: safety at work or environmental directives.
B157: (B) Investments with payback
B158: Investment to increase production capacity and/or profitability (low complexity and implementation time within 1 year).
B160: (C) Major Projects
B161: Investment to secure or increase production capacity and/or profitability (high complexity and implementation time longer than 1 year).
...

Sheet PP_Form
K3: Division | M3: 04
K4: PC | L4: =START!C6 -> 1661 HR Turkey
K5: Project No. | L5: P-12007
C6: Category | D6: [C] Major Project
C8: Priority | D8: NO
C10: Project | D10: Logistic Service Provider For Bornova Counting Center
C12: Project Costs in 1 Euro | D12: ='INVESTMENT per Year'!H21 -> 3013333.3 | F12: thereof Leasing | I12: Budgeted approved
C14: Project Description | D14: Mandatory Deposite System for some beverage packagings will come into force at 2021 depending on the new Environmental Law. 3.business type is expected to be available for this sytem • System Operator • Logistic Company • Counting Center Operator (Antalya and İzmir) The IP is prepared for being a logistic company that delivers packagings to the counting center in Bornova.
C16: Benefit | D16: The new law will give us opportunity to participate the deposite system. That will help us to reach the sources which we can't reach because of the municipality collection contracts. We will have more option to reach the commercial companies.
C18: Remarks
C20: Documentation
C26: Planned start | D26: 44197
C28: Total property an required assets | I28: Efficiency Calculation
C30: MA200 Expend. for setting up & expanding a business | G30: =SUMIF('INVESTMENT per Year'!$E$4:$E$18,C30,'INVESTMENT per Year'!$N$4:$N$18) -> 0 | I30: 11. Additional incomes | M30: =(BusPlanLocation!I42+BusPlanLocation!K42+BusPlanLocation!M42+BusPlanLocation!O42+BusPlanLocation!Q42+BusPlanLocation!S42)/IF(BusPlanLocation!C9="EUR",1,START!$E$18)*1000/D51 -> #REF!
C31: MA210 Concessions, commercial property | G31: =SUMIF('INVESTMENT per Year'!$E$4:$E$18,C31,'INVESTMENT per Year'!$N$4:$N$18) -> 0 | I31: 12. Cost reduction
C32: MA215 Goodwill | G32: =SUMIF('INVESTMENT per Year'!$E$4:$E$18,C32,'INVESTMENT per Year'!$N$4:$N$18) -> 0 | I32: 13. Additional cost (without depr. and financing cost) | M32: =+(M30*D51-(SUM(BusPlanLocation!I92+BusPlanLocation!K92+BusPlanLocation!M92+BusPlanLocation!O92+BusPlanLocation!Q92+BusPlanLocation!S92)/IF(BusPlanLocation!C9="EUR",1,START!$E$18))*1000)/D51 -> #REF!
C33: MA230 Land and similar rights | G33: =SUMIF('INVESTMENT per Year'!$E$4:$E$18,C33,'INVESTMENT per Year'!$N$4:$N$18) -> 0 | I33: 14. Additional EBITDA Contribution | M33: =SUM(M30:M31)-M32 -> #REF!
C34: MA240 Buildings including buildings on third party land | G34: =SUMIF('INVESTMENT per Year'!$E$4:$E$18,C34,'INVESTMENT per Year'!$N$4:$N$18) -> 0
C35: MA250 Technical equipment and machinery | G35: =SUMIF('INVESTMENT per Year'!$E$4:$E$20,C35,'INVESTMENT per Year'!$N$4:$N$20) -> 3640000 | I35: 15. Calc. depr. | M35: =IF(OR(G41="",D52=""),0,G41/D52) -> 1040000
C36: MA260 Other equipment, factory and office equipment | G36: =SUMIF('INVESTMENT per Year'!$E$4:$E$18,C36,'INVESTMENT per Year'!$N$4:$N$18) -> 0 | I36: 16. Additional EBIT Contribution | M36: =M33-M35 -> #REF!
C37: MA300 Shares in affil. companies | G37: =SUMIF('INVESTMENT per Year'!$E$4:$E$18,C37,'INVESTMENT per Year'!$N$4:$N$18) -> 0
C38: 1. Gross Total Property (incl. own services) | G38: =SUM(G30:G37) -> 3640000 | I38: 17. Depreciated lifetime (weighted avg.) in years | M38: ='INVESTMENT per Year'!O21 -> 3.5
I39: 18. Pay back period in years | M39: =IF(M33=0,"",G46/M33) -> #REF!
C40: 2. Residual value of the old equipment | I40: 19. Return on capital employed | M40: =IF(M36=" / ","/",M36/((G41-G34)*0.5+G34+G42)) -> #REF!
C41: 3. Net Total Property | G41: =G38-G40 -> 3640000
C42: 4. Current assets | G42: 0 | I42: Cash Out
C43: 5. Leasing | G43: =G12 -> 0
C44: 6. Expense | G44: 0 | I44: =" Quarter 1 "&START!$C$14 -> Quarter 1 2021 | M44: ='Cashflow per quarter'!G20 -> 3013333.3
C45: 7. Major Repair Expense | G45: 0 | I45: =" Quarter 2 "&START!$C$14 -> Quarter 2 2021 | M45: ='Cashflow per quarter'!H20 -> 0
C46: 8. Invested Capital | G46: =SUM(G41:G45) -> 3640000 | I46: =" Quarter 3 "&START!$C$14 -> Quarter 3 2021 | M46: ='Cashflow per quarter'!I20 -> 0
I47: =" Quarter 4 "&START!$C$14 -> Quarter 4 2021 | M47: ='Cashflow per quarter'!J20 -> 0
C48: 9. Own services | I48: =START!$C$14 -> 2021 | M48: =SUM(M44:M47) -> 3013333.3
C49: 10. Additionally Needed Assets | G49: =G46-G48 -> 3640000 | I49: =" Quarter 1 "&START!$C$14+1 -> Quarter 1 2022 | M49: ='Cashflow per quarter'!M20 -> 0
I50: =" Quarter 2 "&START!$C$14+1 -> Quarter 2 2022 | M50: ='Cashflow per quarter'!N20 -> 0
C51: Planning periods in years | D51: ='EBITDA-Tracking'!M8 -> #REF! | I51: =" Quarter 3 "&START!$C$14+1 -> Quarter 3 2022 | M51: ='Cashflow per quarter'!O20 -> 0
C52: Depreciation in years: | D52: =+'INVESTMENT per Year'!O21 -> 3.5 | I52: =" Quarter 4 "&START!$C$14+1 -> Quarter 4 2022 | M52: ='Cashflow per quarter'!P20 -> 0
I53: =START!$C$14+1 -> 2022 | M53: =SUM(M49:M52) -> 0
I54: =" >= "&START!$C$14+1 -> >= 2022 | M54: =SUM('INVESTMENT per Year'!J21:M21) -> 0
I55: Total Cash Out | M55: =M54+M53+M48 -> 3013333.3
C57: to be filled | E57: Postcalculation on Payback / Benfits needed
...

Sheet INF_PrevYearEUR
C2: Quicklink | J2: ACT Rep - unconsolidated P&L All Depots
J3: 2018-12 YTD | Actual | 190 HR Ens | in 1.000 | unconsolidated
C5: Menu | J5: Status: Approved by Div
C8: Profit Center | M8: 2018-12 YTD | O8: 2018-12 YTD | Q8: Dev. | S8: Total excl. Coll. | U8: 1901 HR Ens | W8: Dev. | Y8: 190100 Sveta Helena | AA8: Dev. | AC8: 190101 Split | AE8: Dev. | AG8: 190102 Osijek | AI8: Dev. | AK8: 190103 Zagreb | AM8: Dev.
M9: Actual | O9: Actual | Q9: in % | S9: Actual | U9: Actual | W9: in % | Y9: Actual | AA9: in % | AC9: Actual | AE9: in % | AG9: Actual | AI9: in % | AK9: Actual | AM9: in %
C10: Year | J10: Acc | K10: Name | M10: in 1.000 EUR | O10: in 1.000 EUR | S10: in 1.000 EUR | U10: in 1.000 EUR | Y10: in 1.000 EUR | AC10: in 1.000 EUR | AG10: in 1.000 EUR | AK10: in 1.000 EUR
J11: M105 | K11: Sales (gross) - Core Business ext.
C12: Month | J12: M106 | K12: Sales (gross) - Core Business affil.
J13: M109 | K13: Total Sales (gross) - Core Business
C14: Currency | J14: M115 | K14: Customer Bonus
J15: M116 | K15: Customer Bonus affil.
C16: Scaling | J16: M120 | K16: Claims
J17: M121 | K17: Claims affil.
J18: M125 | K18: Discount
C19: Comp Column 1 | J19: M126 | K19: Discount affil.
J20: M130 | K20: Freight refund
J21: M131 | K21: Freight refund affil.
J22: M139 | K22: Reduction in Sales - Core Business
J23: M145 | K23: Revenues from trade goods ext.
J24: M146 | K24: Revenues from trade goods affil.
J25: M149 | K25: Sales from trade goods (net)
J26: M155 | K26: Other Sales (net) ext.
J27: M156 | K27: Other Sales (net) affil.
J28: M159 | K28: Other Sales (net)
J29: M179 | K29: TOTAL SALES (net)
J30: M189 | K30: Change in inventory
J31: M199 | K31: OPERATING INCOME
... J143: S | K143: Secondary costs
K144: NET INCOME After Allocation
J146: All Business Types
J147: Papers
J148: Plastics
J149: Refuse Derived Fuels
J150: Metals
J151: Glass
J152: Wood
J153: Final Goods
J154: Compound
J155: Waste
J156: Collection
...

Sheet Calc_INF_PrevYearEUR
B2: =INF_PrevYearEUR!J2 -> ACT Rep - unconsolidated P&L All Depots
B3: =INF_PrevYearEUR!J3 -> 2018-12 YTD | Actual | 190 HR Ens | in 1.000 | unconsolidated
B5: =INF_PrevYearEUR!J5 -> Status: Approved by Div | E5: =E8 -> 2018-12 YTD | F5: =F8 -> 0 | G5: =G8 -> 2018-12 YTD | H5: =H8 -> 0 | I5: =I8 -> Dev. | J5: =J8 -> 0 | K5: =K8 -> Total excl. Coll. | L5: =L8 -> 0 | ... BQ5: =BQ8 -> 0
E6: =IF(E5=0,"",COLUMN()) -> 5 | F6: =IF(F5=0,"",COLUMN()) | G6: =IF(G5=0,"",COLUMN()) -> 7 | H6: =IF(H5=0,"",COLUMN()) | I6: =IF(I5=0,"",COLUMN()) -> 9 | J6: =IF(J5=0,"",COLUMN()) | K6: =IF(K5=0,"",COLUMN()) -> 11 | L6: =IF(L5=0,"",COLUMN()) | ... BQ6: =IF(BQ5=0,"",COLUMN())
B8: =INF_PrevYearEUR!J8 -> 0 | C8: =INF_PrevYearEUR!K8 -> 0 | D8: =INF_PrevYearEUR!L8 -> 0 | E8: =INF_PrevYearEUR!M8 -> 2018-12 YTD | F8: =INF_PrevYearEUR!N8 -> 0 | G8: =INF_PrevYearEUR!O8 -> 2018-12 YTD | H8: =INF_PrevYearEUR!P8 -> 0 | I8: =INF_PrevYearEUR!Q8 -> Dev. | ... BQ8: =INF_PrevYearEUR!BY8 -> 0
B9: =INF_PrevYearEUR!J9 -> 0 | C9: =INF_PrevYearEUR!K9 -> 0 | D9: =INF_PrevYearEUR!L9 -> 0 | E9: =INF_PrevYearEUR!M9 -> Actual | F9: =INF_PrevYearEUR!N9 -> 0 | G9: =INF_PrevYearEUR!O9 -> Actual | H9: =INF_PrevYearEUR!P9 -> 0 | I9: =INF_PrevYearEUR!Q9 -> in % | ... BQ9: =INF_PrevYearEUR!BY9 -> 0
A10: Acc | B10: =INF_PrevYearEUR!J10 -> Acc | C10: =INF_PrevYearEUR!K10 -> Name | D10: =INF_PrevYearEUR!L10 -> 0 | E10: =INF_PrevYearEUR!M10 -> in 1.000 EUR | F10: =INF_PrevYearEUR!N10 -> 0 | G10: =INF_PrevYearEUR!O10 -> in 1.000 EUR | H10: =INF_PrevYearEUR!P10 -> 0 | I10: =INF_PrevYearEUR!Q10 -> 0 | ... BQ10: =INF_PrevYearEUR!BY10 -> 0
A11: =IF(OR(B11=0,B11=""),"",B11&IF(COUNTIF(B11:$B$11,B11)>1,COUNTIF(B11:$B$11,B11),"")) -> M105 | B11: =INF_PrevYearEUR!J11 -> M105 | C11: =INF_PrevYearEUR!K11 -> Sales (gross) - Core Business ext. | D11: =INF_PrevYearEUR!L11 -> 0 | E11: =INF_PrevYearEUR!M11 -> 0 | F11: =INF_PrevYearEUR!N11 -> 0 | G11: =INF_PrevYearEUR!O11 -> 0 | H11: =INF_PrevYearEUR!P11 -> 0 | I11: =INF_PrevYearEUR!Q11 -> 0 | ... BQ11: =INF_PrevYearEUR!BY11 -> 0
A12: =IF(OR(B12=0,B12=""),"",B12&IF(COUNTIF(B$11:$B12,B12)>1,COUNTIF(B$11:$B12,B12),"")) -> M106 | B12: =INF_PrevYearEUR!J12 -> M106 | C12: =INF_PrevYearEUR!K12 -> Sales (gross) - Core Business affil. | D12: =INF_PrevYearEUR!L12 -> 0 | E12: =INF_PrevYearEUR!M12 -> 0 | F12: =INF_PrevYearEUR!N12 -> 0 | G12: =INF_PrevYearEUR!O12 -> 0 | H12: =INF_PrevYearEUR!P12 -> 0 | I12: =INF_PrevYearEUR!Q12 -> 0 | ... BQ12: =INF_PrevYearEUR!BY12 -> 0
A13: =IF(OR(B13=0,B13=""),"",B13&IF(COUNTIF(B$11:$B13,B13)>1,COUNTIF(B$11:$B13,B13),"")) -> M109 | B13: =INF_PrevYearEUR!J13 -> M109 | C13: =INF_PrevYearEUR!K13 -> Total Sales (gross) - Core Business | D13: =INF_PrevYearEUR!L13 -> 0 | E13: =INF_PrevYearEUR!M13 -> 0 | F13: =INF_PrevYearEUR!N13 -> 0 | G13: =INF_PrevYearEUR!O13 -> 0 | H13: =INF_PrevYearEUR!P13 -> 0 | I13: =INF_PrevYearEUR!Q13 -> 0 | ... BQ13: =INF_PrevYearEUR!BY13 -> 0
A14: =IF(OR(B14=0,B14=""),"",B14&IF(COUNTIF(B$11:$B14,B14)>1,COUNTIF(B$11:$B14,B14),"")) -> M115 | B14: =INF_PrevYearEUR!J14 -> M115 | C14: =INF_PrevYearEUR!K14 -> Customer Bonus | D14: =INF_PrevYearEUR!L14 -> 0 | E14: =INF_PrevYearEUR!M14 -> 0 | F14: =INF_PrevYearEUR!N14 -> 0 | G14: =INF_PrevYearEUR!O14 -> 0 | H14: =INF_PrevYearEUR!P14 -> 0 | I14: =INF_PrevYearEUR!Q14 -> 0 | ... BQ14: =INF_PrevYearEUR!BY14 -> 0
A15: =IF(OR(B15=0,B15=""),"",B15&IF(COUNTIF(B$11:$B15,B15)>1,COUNTIF(B$11:$B15,B15),"")) -> M116 | B15: =INF_PrevYearEUR!J15 -> M116 | C15: =INF_PrevYearEUR!K15 -> Customer Bonus affil. | D15: =INF_PrevYearEUR!L15 -> 0 | E15: =INF_PrevYearEUR!M15 -> 0 | F15: =INF_PrevYearEUR!N15 -> 0 | G15: =INF_PrevYearEUR!O15 -> 0 | H15: =INF_PrevYearEUR!P15 -> 0 | I15: =INF_PrevYearEUR!Q15 -> 0 | ... BQ15: =INF_PrevYearEUR!BY15 -> 0
A16: =IF(OR(B16=0,B16=""),"",B16&IF(COUNTIF(B$11:$B16,B16)>1,COUNTIF(B$11:$B16,B16),"")) -> M120 | B16: =INF_PrevYearEUR!J16 -> M120 | C16: =INF_PrevYearEUR!K16 -> Claims | D16: =INF_PrevYearEUR!L16 -> 0 | E16: =INF_PrevYearEUR!M16 -> 0 | F16: =INF_PrevYearEUR!N16 -> 0 | G16: =INF_PrevYearEUR!O16 -> 0 | H16: =INF_PrevYearEUR!P16 -> 0 | I16: =INF_PrevYearEUR!Q16 -> 0 | ... BQ16: =INF_PrevYearEUR!BY16 -> 0
A17: =IF(OR(B17=0,B17=""),"",B17&IF(COUNTIF(B$11:$B17,B17)>1,COUNTIF(B$11:$B17,B17),"")) -> M121 | B17: =INF_PrevYearEUR!J17 -> M121 | C17: =INF_PrevYearEUR!K17 -> Claims affil. | D17: =INF_PrevYearEUR!L17 -> 0 | E17: =INF_PrevYearEUR!M17 -> 0 | F17: =INF_PrevYearEUR!N17 -> 0 | G17: =INF_PrevYearEUR!O17 -> 0 | H17: =INF_PrevYearEUR!P17 -> 0 | I17: =INF_PrevYearEUR!Q17 -> 0 | ... BQ17: =INF_PrevYearEUR!BY17 -> 0
A18: =IF(OR(B18=0,B18=""),"",B18&IF(COUNTIF(B$11:$B18,B18)>1,COUNTIF(B$11:$B18,B18),"")) -> M125 | B18: =INF_PrevYearEUR!J18 -> M125 | C18: =INF_PrevYearEUR!K18 -> Discount | D18: =INF_PrevYearEUR!L18 -> 0 | E18: =INF_PrevYearEUR!M18 -> 0 | F18: =INF_PrevYearEUR!N18 -> 0 | G18: =INF_PrevYearEUR!O18 -> 0 | H18: =INF_PrevYearEUR!P18 -> 0 | I18: =INF_PrevYearEUR!Q18 -> 0 | ... BQ18: =INF_PrevYearEUR!BY18 -> 0
A19: =IF(OR(B19=0,B19=""),"",B19&IF(COUNTIF(B$11:$B19,B19)>1,COUNTIF(B$11:$B19,B19),"")) -> M126 | B19: =INF_PrevYearEUR!J19 -> M126 | C19: =INF_PrevYearEUR!K19 -> Discount affil. | D19: =INF_PrevYearEUR!L19 -> 0 | E19: =INF_PrevYearEUR!M19 -> 0 | F19: =INF_PrevYearEUR!N19 -> 0 | G19: =INF_PrevYearEUR!O19 -> 0 | H19: =INF_PrevYearEUR!P19 -> 0 | I19: =INF_PrevYearEUR!Q19 -> 0 | ... BQ19: =INF_PrevYearEUR!BY19 -> 0
A20: =IF(OR(B20=0,B20=""),"",B20&IF(COUNTIF(B$11:$B20,B20)>1,COUNTIF(B$11:$B20,B20),"")) -> M130 | B20: =INF_PrevYearEUR!J20 -> M130 | C20: =INF_PrevYearEUR!K20 -> Freight refund | D20: =INF_PrevYearEUR!L20 -> 0 | E20: =INF_PrevYearEUR!M20 -> 0 | F20: =INF_PrevYearEUR!N20 -> 0 | G20: =INF_PrevYearEUR!O20 -> 0 | H20: =INF_PrevYearEUR!P20 -> 0 | I20: =INF_PrevYearEUR!Q20 -> 0 | ... BQ20: =INF_PrevYearEUR!BY20 -> 0
A21: =IF(OR(B21=0,B21=""),"",B21&IF(COUNTIF(B$11:$B21,B21)>1,COUNTIF(B$11:$B21,B21),"")) -> M131 | B21: =INF_PrevYearEUR!J21 -> M131 | C21: =INF_PrevYearEUR!K21 -> Freight refund affil. | D21: =INF_PrevYearEUR!L21 -> 0 | E21: =INF_PrevYearEUR!M21 -> 0 | F21: =INF_PrevYearEUR!N21 -> 0 | G21: =INF_PrevYearEUR!O21 -> 0 | H21: =INF_PrevYearEUR!P21 -> 0 | I21: =INF_PrevYearEUR!Q21 -> 0 | ... BQ21: =INF_PrevYearEUR!BY21 -> 0
A22: =IF(OR(B22=0,B22=""),"",B22&IF(COUNTIF(B$11:$B22,B22)>1,COUNTIF(B$11:$B22,B22),"")) -> M139 | B22: =INF_PrevYearEUR!J22 -> M139 | C22: =INF_PrevYearEUR!K22 -> Reduction in Sales - Core Business | D22: =INF_PrevYearEUR!L22 -> 0 | E22: =INF_PrevYearEUR!M22 -> 0 | F22: =INF_PrevYearEUR!N22 -> 0 | G22: =INF_PrevYearEUR!O22 -> 0 | H22: =INF_PrevYearEUR!P22 -> 0 | I22: =INF_PrevYearEUR!Q22 -> 0 | ... BQ22: =INF_PrevYearEUR!BY22 -> 0
A23: =IF(OR(B23=0,B23=""),"",B23&IF(COUNTIF(B$11:$B23,B23)>1,COUNTIF(B$11:$B23,B23),"")) -> M145 | B23: =INF_PrevYearEUR!J23 -> M145 | C23: =INF_PrevYearEUR!K23 -> Revenues from trade goods ext. | D23: =INF_PrevYearEUR!L23 -> 0 | E23: =INF_PrevYearEUR!M23 -> 0 | F23: =INF_PrevYearEUR!N23 -> 0 | G23: =INF_PrevYearEUR!O23 -> 0 | H23: =INF_PrevYearEUR!P23 -> 0 | I23: =INF_PrevYearEUR!Q23 -> 0 | ... BQ23: =INF_PrevYearEUR!BY23 -> 0
... A143: =IF(OR(B143=0,B143=""),"",B143&IF(COUNTIF(B$11:$B143,B143)>1,COUNTIF(B$11:$B143,B143),"")) -> S | B143: =INF_PrevYearEUR!J143 -> S | C143: =INF_PrevYearEUR!K143 -> Secondary costs | D143: =INF_PrevYearEUR!L143 -> 0 | E143: =INF_PrevYearEUR!M143 -> 0 | F143: =INF_PrevYearEUR!N143 -> 0 | G143: =INF_PrevYearEUR!O143 -> 0 | H143: =INF_PrevYearEUR!P143 -> 0 | I143: =INF_PrevYearEUR!Q143 -> 0 | ... BQ143: =INF_PrevYearEUR!BY143 -> 0
A144: =IF(OR(B144=0,B144=""),"",B144&IF(COUNTIF(B$11:$B144,B144)>1,COUNTIF(B$11:$B144,B144),"")) | B144: =INF_PrevYearEUR!J145 -> 0 | D144: =INF_PrevYearEUR!L145 -> 0 | E144: =INF_PrevYearEUR!M145 -> 0 | F144: =INF_PrevYearEUR!N145 -> 0 | G144: =INF_PrevYearEUR!O145 -> 0 | H144: =INF_PrevYearEUR!P145 -> 0 | I144: =INF_PrevYearEUR!Q145 -> 0 | J144: =INF_PrevYearEUR!R145 -> 0 | K144: =INF_PrevYearEUR!S145 -> 0 | ... BQ144: =INF_PrevYearEUR!BY145 -> 0
A145: =IF(OR(B145=0,B145=""),"",B145&IF(COUNTIF(B$11:$B145,B145)>1,COUNTIF(B$11:$B145,B145),"")) -> All Business Types | B145: =INF_PrevYearEUR!J146 -> All Business Types | D145: =INF_PrevYearEUR!L146 -> 0 | E145: =INF_PrevYearEUR!M146 -> 0 | F145: =INF_PrevYearEUR!N146 -> 0 | G145: =INF_PrevYearEUR!O146 -> 0 | H145: =INF_PrevYearEUR!P146 -> 0 | I145: =INF_PrevYearEUR!Q146 -> 0 | J145: =INF_PrevYearEUR!R146 -> 0 | K145: =INF_PrevYearEUR!S146 -> 0 | ... BQ145: =INF_PrevYearEUR!BY146 -> 0
A146: =IF(OR(B146=0,B146=""),"",B146&IF(COUNTIF(B$11:$B146,B146)>1,COUNTIF(B$11:$B146,B146),"")) -> Papers | B146: =INF_PrevYearEUR!J147 -> Papers | D146: =INF_PrevYearEUR!L147 -> 0 | E146: =INF_PrevYearEUR!M147 -> 0 | F146: =INF_PrevYearEUR!N147 -> 0 | G146: =INF_PrevYearEUR!O147 -> 0 | H146: =INF_PrevYearEUR!P147 -> 0 | I146: =INF_PrevYearEUR!Q147 -> 0 | J146: =INF_PrevYearEUR!R147 -> 0 | K146: =INF_PrevYearEUR!S147 -> 0 | ... BQ146: =INF_PrevYearEUR!BY147 -> 0
A147: =IF(OR(B147=0,B147=""),"",B147&IF(COUNTIF(B$11:$B147,B147)>1,COUNTIF(B$11:$B147,B147),"")) -> Plastics | B147: =INF_PrevYearEUR!J148 -> Plastics | D147: =INF_PrevYearEUR!L148 -> 0 | E147: =INF_PrevYearEUR!M148 -> 0 | F147: =INF_PrevYearEUR!N148 -> 0 | G147: =INF_PrevYearEUR!O148 -> 0 | H147: =INF_PrevYearEUR!P148 -> 0 | I147: =INF_PrevYearEUR!Q148 -> 0 | J147: =INF_PrevYearEUR!R148 -> 0 | K147: =INF_PrevYearEUR!S148 -> 0 | ... BQ147: =INF_PrevYearEUR!BY148 -> 0
A148: =IF(OR(B148=0,B148=""),"",B148&IF(COUNTIF(B$11:$B148,B148)>1,COUNTIF(B$11:$B148,B148),"")) -> Refuse Derived Fuels | B148: =INF_PrevYearEUR!J149 -> Refuse Derived Fuels | D148: =INF_PrevYearEUR!L149 -> 0 | E148: =INF_PrevYearEUR!M149 -> 0 | F148: =INF_PrevYearEUR!N149 -> 0 | G148: =INF_PrevYearEUR!O149 -> 0 | H148: =INF_PrevYearEUR!P149 -> 0 | I148: =INF_PrevYearEUR!Q149 -> 0 | J148: =INF_PrevYearEUR!R149 -> 0 | K148: =INF_PrevYearEUR!S149 -> 0 | ... BQ148: =INF_PrevYearEUR!BY149 -> 0
A149: =IF(OR(B149=0,B149=""),"",B149&IF(COUNTIF(B$11:$B149,B149)>1,COUNTIF(B$11:$B149,B149),"")) -> Metals | B149: =INF_PrevYearEUR!J150 -> Metals | D149: =INF_PrevYearEUR!L150 -> 0 | E149: =INF_PrevYearEUR!M150 -> 0 | F149: =INF_PrevYearEUR!N150 -> 0 | G149: =INF_PrevYearEUR!O150 -> 0 | H149: =INF_PrevYearEUR!P150 -> 0 | I149: =INF_PrevYearEUR!Q150 -> 0 | J149: =INF_PrevYearEUR!R150 -> 0 | K149: =INF_PrevYearEUR!S150 -> 0 | ... BQ149: =INF_PrevYearEUR!BY150 -> 0
A150: =IF(OR(B150=0,B150=""),"",B150&IF(COUNTIF(B$11:$B150,B150)>1,COUNTIF(B$11:$B150,B150),"")) -> Glass | B150: =INF_PrevYearEUR!J151 -> Glass | D150: =INF_PrevYearEUR!L151 -> 0 | E150: =INF_PrevYearEUR!M151 -> 0 | F150: =INF_PrevYearEUR!N151 -> 0 | G150: =INF_PrevYearEUR!O151 -> 0 | H150: =INF_PrevYearEUR!P151 -> 0 | I150: =INF_PrevYearEUR!Q151 -> 0 | J150: =INF_PrevYearEUR!R151 -> 0 | K150: =INF_PrevYearEUR!S151 -> 0 | ... BQ150: =INF_PrevYearEUR!BY151 -> 0
A151: =IF(OR(B151=0,B151=""),"",B151&IF(COUNTIF(B$11:$B151,B151)>1,COUNTIF(B$11:$B151,B151),"")) -> Wood | B151: =INF_PrevYearEUR!J152 -> Wood | D151: =INF_PrevYearEUR!L152 -> 0 | E151: =INF_PrevYearEUR!M152 -> 0 | F151: =INF_PrevYearEUR!N152 -> 0 | G151: =INF_PrevYearEUR!O152 -> 0 | H151: =INF_PrevYearEUR!P152 -> 0 | I151: =INF_PrevYearEUR!Q152 -> 0 | J151: =INF_PrevYearEUR!R152 -> 0 | K151: =INF_PrevYearEUR!S152 -> 0 | ... BQ151: =INF_PrevYearEUR!BY152 -> 0
A152: =IF(OR(B152=0,B152=""),"",B152&IF(COUNTIF(B$11:$B152,B152)>1,COUNTIF(B$11:$B152,B152),"")) -> Final Goods | B152: =INF_PrevYearEUR!J153 -> Final Goods | D152: =INF_PrevYearEUR!L153 -> 0 | E152: =INF_PrevYearEUR!M153 -> 0 | F152: =INF_PrevYearEUR!N153 -> 0 | G152: =INF_PrevYearEUR!O153 -> 0 | H152: =INF_PrevYearEUR!P153 -> 0 | I152: =INF_PrevYearEUR!Q153 -> 0 | J152: =INF_PrevYearEUR!R153 -> 0 | K152: =INF_PrevYearEUR!S153 -> 0 | ... BQ152: =INF_PrevYearEUR!BY153 -> 0
A153: =IF(OR(B153=0,B153=""),"",B153&IF(COUNTIF(B$11:$B153,B153)>1,COUNTIF(B$11:$B153,B153),"")) -> Compound | B153: =INF_PrevYearEUR!J154 -> Compound | D153: =INF_PrevYearEUR!L154 -> 0 | E153: =INF_PrevYearEUR!M154 -> 0 | F153: =INF_PrevYearEUR!N154 -> 0 | G153: =INF_PrevYearEUR!O154 -> 0 | H153: =INF_PrevYearEUR!P154 -> 0 | I153: =INF_PrevYearEUR!Q154 -> 0 | J153: =INF_PrevYearEUR!R154 -> 0 | K153: =INF_PrevYearEUR!S154 -> 0 | ... BQ153: =INF_PrevYearEUR!BY154 -> 0
A154: =IF(OR(B154=0,B154=""),"",B154&IF(COUNTIF(B$11:$B154,B154)>1,COUNTIF(B$11:$B154,B154),"")) -> Waste | B154: =INF_PrevYearEUR!J155 -> Waste | D154: =INF_PrevYearEUR!L155 -> 0 | E154: =INF_PrevYearEUR!M155 -> 0 | F154: =INF_PrevYearEUR!N155 -> 0 | G154: =INF_PrevYearEUR!O155 -> 0 | H154: =INF_PrevYearEUR!P155 -> 0 | I154: =INF_PrevYearEUR!Q155 -> 0 | J154: =INF_PrevYearEUR!R155 -> 0 | K154: =INF_PrevYearEUR!S155 -> 0 | ... BQ154: =INF_PrevYearEUR!BY155 -> 0
A155: =IF(OR(B155=0,B155=""),"",B155&IF(COUNTIF(B$11:$B155,B155)>1,COUNTIF(B$11:$B155,B155),"")) -> Collection | B155: =INF_PrevYearEUR!J156 -> Collection | D155: =INF_PrevYearEUR!L156 -> 0 | E155: =INF_PrevYearEUR!M156 -> 0 | F155: =INF_PrevYearEUR!N156 -> 0 | G155: =INF_PrevYearEUR!O156 -> 0 | H155: =INF_PrevYearEUR!P156 -> 0 | I155: =INF_PrevYearEUR!Q156 -> 0 | J155: =INF_PrevYearEUR!R156 -> 0 | K155: =INF_PrevYearEUR!S156 -> 0 | ... BQ155: =INF_PrevYearEUR!BY156 -> 0
... A330: =IF(OR(B330=0,B330=""),"",B330&IF(COUNTIF(B$11:$B330,B330)>1,COUNTIF(B$11:$B330,B330),"")) | B330: =INF_PrevYearEUR!J331 -> 0 | D330: =INF_PrevYearEUR!L331 -> 0 | E330: =INF_PrevYearEUR!M331 -> 0 | F330: =INF_PrevYearEUR!N331 -> 0 | G330: =INF_PrevYearEUR!O331 -> 0 | H330: =INF_PrevYearEUR!P331 -> 0 | I330: =INF_PrevYearEUR!Q331 -> 0 | J330: =INF_PrevYearEUR!R331 -> 0 | K330: =INF_PrevYearEUR!S331 -> 0 | ... BQ330: =INF_PrevYearEUR!BY331 -> 0

Sheet INF_FC_EUR
C2: Quicklink | J2: FC Rep - unconsolidated P&L All Depots
J3: FC 2019-03 | 190 HR Ens | in 1.000
C5: Menu | J5: Status: Finished
C8: Profit Center | M8: 2013-12 YTD | O8: 2019-12 YTD | Q8: Dev. | S8: Total excl. Coll. | U8: 1901 HR Ens | W8: Dev. | Y8: 190100 Sveta Helena | AA8: Dev. | AC8: 190101 Split | AE8: Dev. | AG8: 190102 Osijek | AI8: Dev. | AK8: 190103 Zagreb | AM8: Dev.
M9: Actual | O9: FC 2019-01 | Q9: in % | S9: FC 2019-01 | U9: FC 2019-01 | W9: in % | Y9: FC 2019-01 | AA9: in % | AC9: FC 2019-01 | AE9: in % | AG9: FC 2019-01 | AI9: in % | AK9: FC 2019-01 | AM9: in %
C10: Forecast Scenario (Planning) | J10: Acc | K10: Name | M10: in 1.000 EUR | O10: in 1.000 EUR | S10: in 1.000 EUR | U10: in 1.000 EUR | Y10: in 1.000 EUR | AC10: in 1.000 EUR | AG10: in 1.000 EUR | AK10: in 1.000 EUR
J11: M105 | K11: Sales (gross) - Core Business ext.
C12: MTP-Year | J12: M106 | K12: Sales (gross) - Core Business affil.
J13: M109 | K13: Total Sales (gross) - Core Business
C14: Currency | J14: M115 | K14: Customer Bonus
J15: M116 | K15: Customer Bonus affil.
C16: Scaling | J16: M120 | K16: Claims
J17: M121 | K17: Claims affil.
J18: M125 | K18: Discount
C19: Comp Column 1 | J19: M126 | K19: Discount affil.
J20: M130 | K20: Freight refund
J21: M131 | K21: Freight refund affil.
J22: M139 | K22: Reduction in Sales - Core Business
J23: M145 | K23: Revenues from trade goods ext.
J24: M146 | K24: Revenues from trade goods affil.
J25: M149 | K25: Sales from trade goods (net)
J26: M155 | K26: Other Sales (net) ext.
J27: M156 | K27: Other Sales (net) affil.
J28: M159 | K28: Other Sales (net)
J29: M179 | K29: TOTAL SALES (net)
J30: M189 | K30: Change in inventory
J31: M199 | K31: OPERATING INCOME
... J140: M999 | K140: NET INCOME
K142: Exchange Rate ....
J144: S | K144: Secondary costs
K145: NET INCOME After Allocation
J147: All Business Types
J148: Papers
J149: Plastics
J150: Refuse Derived Fuels
J151: Metals
J152: Glass
J153: Wood
J154: Final Goods
J155: Compound
...

Sheet Calc_INF_FC_EUR
B2: =INF_FC_EUR!J2 -> FC Rep - unconsolidated P&L All Depots
B3: =INF_FC_EUR!J3 -> FC 2019-03 | 190 HR Ens | in 1.000
B5: =INF_FC_EUR!J5 -> Status: Finished | E5: =E8 -> 2013-12 YTD | F5: =F8 -> 0 | G5: =G8 -> 2019-12 YTD | H5: =H8 -> 0 | I5: =I8 -> Dev. | J5: =J8 -> 0 | K5: =K8 -> Total excl. Coll. | L5: =L8 -> 0 | ... BQ5: =BQ8 -> 0
E6: =IF(E5=0,"",COLUMN()) -> 5 | F6: =IF(F5=0,"",COLUMN()) | G6: =IF(G5=0,"",COLUMN()) -> 7 | H6: =IF(H5=0,"",COLUMN()) | I6: =IF(I5=0,"",COLUMN()) -> 9 | J6: =IF(J5=0,"",COLUMN()) | K6: =IF(K5=0,"",COLUMN()) -> 11 | L6: =IF(L5=0,"",COLUMN()) | ... BQ6: =IF(BQ5=0,"",COLUMN())
B8: =INF_FC_EUR!J8 -> 0 | C8: =INF_FC_EUR!K8 -> 0 | D8: =INF_FC_EUR!L8 -> 0 | E8: =INF_FC_EUR!M8 -> 2013-12 YTD | F8: =INF_FC_EUR!N8 -> 0 | G8: =INF_FC_EUR!O8 -> 2019-12 YTD | H8: =INF_FC_EUR!P8 -> 0 | I8: =INF_FC_EUR!Q8 -> Dev. | ... BQ8: =INF_FC_EUR!BY8 -> 0
B9: =INF_FC_EUR!J9 -> 0 | C9: =INF_FC_EUR!K9 -> 0 | D9: =INF_FC_EUR!L9 -> 0 | E9: =INF_FC_EUR!M9 -> Actual | F9: =INF_FC_EUR!N9 -> 0 | G9: =INF_FC_EUR!O9 -> FC 2019-01 | H9: =INF_FC_EUR!P9 -> 0 | I9: =INF_FC_EUR!Q9 -> in % | ... BQ9: =INF_FC_EUR!BY9 -> 0
A10: Acc | B10: =INF_FC_EUR!J10 -> Acc | C10: =INF_FC_EUR!K10 -> Name | D10: =INF_FC_EUR!L10 -> 0 | E10: =INF_FC_EUR!M10 -> in 1.000 EUR | F10: =INF_FC_EUR!N10 -> 0 | G10: =INF_FC_EUR!O10 -> in 1.000 EUR | H10: =INF_FC_EUR!P10 -> 0 | I10: =INF_FC_EUR!Q10 -> 0 | ... BQ10: =INF_FC_EUR!BY10 -> 0
A11: =IF(OR(B11=0,B11=""),"",B11&IF(COUNTIF(B11:$B$11,B11)>1,COUNTIF(B11:$B$11,B11),"")) -> M105 | B11: =INF_FC_EUR!J11 -> M105 | C11: =INF_FC_EUR!K11 -> Sales (gross) - Core Business ext. | D11: =INF_FC_EUR!L11 -> 0 | E11: =INF_FC_EUR!M11 -> 0 | F11: =INF_FC_EUR!N11 -> 0 | G11: =INF_FC_EUR!O11 -> 0 | H11: =INF_FC_EUR!P11 -> 0 | I11: =INF_FC_EUR!Q11 -> 0 | ... BQ11: =INF_FC_EUR!BY11 -> 0
A12: =IF(OR(B12=0,B12=""),"",B12&IF(COUNTIF(B$11:$B12,B12)>1,COUNTIF(B$11:$B12,B12),"")) -> M106 | B12: =INF_FC_EUR!J12 -> M106 | C12: =INF_FC_EUR!K12 -> Sales (gross) - Core Business affil. | D12: =INF_FC_EUR!L12 -> 0 | E12: =INF_FC_EUR!M12 -> 0 | F12: =INF_FC_EUR!N12 -> 0 | G12: =INF_FC_EUR!O12 -> 0 | H12: =INF_FC_EUR!P12 -> 0 | I12: =INF_FC_EUR!Q12 -> 0 | ... BQ12: =INF_FC_EUR!BY12 -> 0
A13: =IF(OR(B13=0,B13=""),"",B13&IF(COUNTIF(B$11:$B13,B13)>1,COUNTIF(B$11:$B13,B13),"")) -> M109 | B13: =INF_FC_EUR!J13 -> M109 | C13: =INF_FC_EUR!K13 -> Total Sales (gross) - Core Business | D13: =INF_FC_EUR!L13 -> 0 | E13: =INF_FC_EUR!M13 -> 0 | F13: =INF_FC_EUR!N13 -> 0 | G13: =INF_FC_EUR!O13 -> 0 | H13: =INF_FC_EUR!P13 -> 0 | I13: =INF_FC_EUR!Q13 -> 0 | ... BQ13: =INF_FC_EUR!BY13 -> 0
A14: =IF(OR(B14=0,B14=""),"",B14&IF(COUNTIF(B$11:$B14,B14)>1,COUNTIF(B$11:$B14,B14),"")) -> M115 | B14: =INF_FC_EUR!J14 -> M115 | C14: =INF_FC_EUR!K14 -> Customer Bonus | D14: =INF_FC_EUR!L14 -> 0 | E14: =INF_FC_EUR!M14 -> 0 | F14: =INF_FC_EUR!N14 -> 0 | G14: =INF_FC_EUR!O14 -> 0 | H14: =INF_FC_EUR!P14 -> 0 | I14: =INF_FC_EUR!Q14 -> 0 | ... BQ14: =INF_FC_EUR!BY14 -> 0
A15: =IF(OR(B15=0,B15=""),"",B15&IF(COUNTIF(B$11:$B15,B15)>1,COUNTIF(B$11:$B15,B15),"")) -> M116 | B15: =INF_FC_EUR!J15 -> M116 | C15: =INF_FC_EUR!K15 -> Customer Bonus affil. | D15: =INF_FC_EUR!L15 -> 0 | E15: =INF_FC_EUR!M15 -> 0 | F15: =INF_FC_EUR!N15 -> 0 | G15: =INF_FC_EUR!O15 -> 0 | H15: =INF_FC_EUR!P15 -> 0 | I15: =INF_FC_EUR!Q15 -> 0 | ... BQ15: =INF_FC_EUR!BY15 -> 0
A16: =IF(OR(B16=0,B16=""),"",B16&IF(COUNTIF(B$11:$B16,B16)>1,COUNTIF(B$11:$B16,B16),"")) -> M120 | B16: =INF_FC_EUR!J16 -> M120 | C16: =INF_FC_EUR!K16 -> Claims | D16: =INF_FC_EUR!L16 -> 0 | E16: =INF_FC_EUR!M16 -> 0 | F16: =INF_FC_EUR!N16 -> 0 | G16: =INF_FC_EUR!O16 -> 0 | H16: =INF_FC_EUR!P16 -> 0 | I16: =INF_FC_EUR!Q16 -> 0 | ... BQ16: =INF_FC_EUR!BY16 -> 0
A17: =IF(OR(B17=0,B17=""),"",B17&IF(COUNTIF(B$11:$B17,B17)>1,COUNTIF(B$11:$B17,B17),"")) -> M121 | B17: =INF_FC_EUR!J17 -> M121 | C17: =INF_FC_EUR!K17 -> Claims affil. | D17: =INF_FC_EUR!L17 -> 0 | E17: =INF_FC_EUR!M17 -> 0 | F17: =INF_FC_EUR!N17 -> 0 | G17: =INF_FC_EUR!O17 -> 0 | H17: =INF_FC_EUR!P17 -> 0 | I17: =INF_FC_EUR!Q17 -> 0 | ... BQ17: =INF_FC_EUR!BY17 -> 0
A18: =IF(OR(B18=0,B18=""),"",B18&IF(COUNTIF(B$11:$B18,B18)>1,COUNTIF(B$11:$B18,B18),"")) -> M125 | B18: =INF_FC_EUR!J18 -> M125 | C18: =INF_FC_EUR!K18 -> Discount | D18: =INF_FC_EUR!L18 -> 0 | E18: =INF_FC_EUR!M18 -> 0 | F18: =INF_FC_EUR!N18 -> 0 | G18: =INF_FC_EUR!O18 -> 0 | H18: =INF_FC_EUR!P18 -> 0 | I18: =INF_FC_EUR!Q18 -> 0 | ... BQ18: =INF_FC_EUR!BY18 -> 0
A19: =IF(OR(B19=0,B19=""),"",B19&IF(COUNTIF(B$11:$B19,B19)>1,COUNTIF(B$11:$B19,B19),"")) -> M126 | B19: =INF_FC_EUR!J19 -> M126 | C19: =INF_FC_EUR!K19 -> Discount affil. | D19: =INF_FC_EUR!L19 -> 0 | E19: =INF_FC_EUR!M19 -> 0 | F19: =INF_FC_EUR!N19 -> 0 | G19: =INF_FC_EUR!O19 -> 0 | H19: =INF_FC_EUR!P19 -> 0 | I19: =INF_FC_EUR!Q19 -> 0 | ... BQ19: =INF_FC_EUR!BY19 -> 0
A20: =IF(OR(B20=0,B20=""),"",B20&IF(COUNTIF(B$11:$B20,B20)>1,COUNTIF(B$11:$B20,B20),"")) -> M130 | B20: =INF_FC_EUR!J20 -> M130 | C20: =INF_FC_EUR!K20 -> Freight refund | D20: =INF_FC_EUR!L20 -> 0 | E20: =INF_FC_EUR!M20 -> 0 | F20: =INF_FC_EUR!N20 -> 0 | G20: =INF_FC_EUR!O20 -> 0 | H20: =INF_FC_EUR!P20 -> 0 | I20: =INF_FC_EUR!Q20 -> 0 | ... BQ20: =INF_FC_EUR!BY20 -> 0
A21: =IF(OR(B21=0,B21=""),"",B21&IF(COUNTIF(B$11:$B21,B21)>1,COUNTIF(B$11:$B21,B21),"")) -> M131 | B21: =INF_FC_EUR!J21 -> M131 | C21: =INF_FC_EUR!K21 -> Freight refund affil. | D21: =INF_FC_EUR!L21 -> 0 | E21: =INF_FC_EUR!M21 -> 0 | F21: =INF_FC_EUR!N21 -> 0 | G21: =INF_FC_EUR!O21 -> 0 | H21: =INF_FC_EUR!P21 -> 0 | I21: =INF_FC_EUR!Q21 -> 0 | ... BQ21: =INF_FC_EUR!BY21 -> 0
A22: =IF(OR(B22=0,B22=""),"",B22&IF(COUNTIF(B$11:$B22,B22)>1,COUNTIF(B$11:$B22,B22),"")) -> M139 | B22: =INF_FC_EUR!J22 -> M139 | C22: =INF_FC_EUR!K22 -> Reduction in Sales - Core Business | D22: =INF_FC_EUR!L22 -> 0 | E22: =INF_FC_EUR!M22 -> 0 | F22: =INF_FC_EUR!N22 -> 0 | G22: =INF_FC_EUR!O22 -> 0 | H22: =INF_FC_EUR!P22 -> 0 | I22: =INF_FC_EUR!Q22 -> 0 | ... BQ22: =INF_FC_EUR!BY22 -> 0
A23: =IF(OR(B23=0,B23=""),"",B23&IF(COUNTIF(B$11:$B23,B23)>1,COUNTIF(B$11:$B23,B23),"")) -> M145 | B23: =INF_FC_EUR!J23 -> M145 | C23: =INF_FC_EUR!K23 -> Revenues from trade goods ext. | D23: =INF_FC_EUR!L23 -> 0 | E23: =INF_FC_EUR!M23 -> 0 | F23: =INF_FC_EUR!N23 -> 0 | G23: =INF_FC_EUR!O23 -> 0 | H23: =INF_FC_EUR!P23 -> 0 | I23: =INF_FC_EUR!Q23 -> 0 | ... BQ23: =INF_FC_EUR!BY23 -> 0
... A140: =IF(OR(B140=0,B140=""),"",B140&IF(COUNTIF(B$11:$B140,B140)>1,COUNTIF(B$11:$B140,B140),"")) -> M999 | B140: =INF_FC_EUR!J140 -> M999 | C140: =INF_FC_EUR!K140 -> NET INCOME | D140: =INF_FC_EUR!L140 -> 0 | E140: =INF_FC_EUR!M140 -> 0 | F140: =INF_FC_EUR!N140 -> 0 | G140: =INF_FC_EUR!O140 -> 0 | H140: =INF_FC_EUR!P140 -> 0 | I140: =INF_FC_EUR!Q140 -> 0 | ... BQ140: =INF_FC_EUR!BY140 -> 0
A141: =IF(OR(B141=0,B141=""),"",B141&IF(COUNTIF(B$11:$B141,B141)>1,COUNTIF(B$11:$B141,B141),"")) | B141: =INF_FC_EUR!J142 -> 0 | C141: =INF_FC_EUR!K142 -> Exchange Rate .... | D141: =INF_FC_EUR!L142 -> 0 | E141: =INF_FC_EUR!M142 -> 0 | F141: =INF_FC_EUR!N142 -> 0 | G141: =INF_FC_EUR!O142 -> 0 | H141: =INF_FC_EUR!P142 -> 0 | I141: =INF_FC_EUR!Q142 -> 0 | ... BQ141: =INF_FC_EUR!BY142 -> 0
A142: =IF(OR(B142=0,B142=""),"",B142&IF(COUNTIF(B$11:$B142,B142)>1,COUNTIF(B$11:$B142,B142),"")) | B142: =INF_FC_EUR!J143 -> 0 | C142: =INF_FC_EUR!K143 -> 0 | D142: =INF_FC_EUR!L143 -> 0 | E142: =INF_FC_EUR!M143 -> 0 | F142: =INF_FC_EUR!N143 -> 0 | G142: =INF_FC_EUR!O143 -> 0 | H142: =INF_FC_EUR!P143 -> 0 | I142: =INF_FC_EUR!Q143 -> 0 | ... BQ142: =INF_FC_EUR!BY143 -> 0
A143: =IF(OR(B143=0,B143=""),"",B143&IF(COUNTIF(B$11:$B143,B143)>1,COUNTIF(B$11:$B143,B143),"")) -> S | B143: =INF_FC_EUR!J144 -> S | C143: =INF_FC_EUR!K144 -> Secondary costs | D143: =INF_FC_EUR!L144 -> 0 | E143: =INF_FC_EUR!M144 -> 0 | F143: =INF_FC_EUR!N144 -> 0 | G143: =INF_FC_EUR!O144 -> 0 | H143: =INF_FC_EUR!P144 -> 0 | I143: =INF_FC_EUR!Q144 -> 0 | ... BQ143: =INF_FC_EUR!BY144 -> 0
A144: =IF(OR(B144=0,B144=""),"",B144&IF(COUNTIF(B$11:$B144,B144)>1,COUNTIF(B$11:$B144,B144),"")) | B144: =INF_FC_EUR!J145 -> 0 | D144: =INF_FC_EUR!L145 -> 0 | E144: =INF_FC_EUR!M145 -> 0 | F144: =INF_FC_EUR!N145 -> 0 | G144: =INF_FC_EUR!O145 -> 0 | H144: =INF_FC_EUR!P145 -> 0 | I144: =INF_FC_EUR!Q145 -> 0 | J144: =INF_FC_EUR!R145 -> 0 | K144: =INF_FC_EUR!S145 -> 0 | ... BQ144: =INF_FC_EUR!BY145 -> 0
A145: =IF(OR(B145=0,B145=""),"",B145&IF(COUNTIF(B$11:$B145,B145)>1,COUNTIF(B$11:$B145,B145),"")) | B145: =INF_FC_EUR!J146 -> 0 | D145: =INF_FC_EUR!L146 -> 0 | E145: =INF_FC_EUR!M146 -> 0 | F145: =INF_FC_EUR!N146 -> 0 | G145: =INF_FC_EUR!O146 -> 0 | H145: =INF_FC_EUR!P146 -> 0 | I145: =INF_FC_EUR!Q146 -> 0 | J145: =INF_FC_EUR!R146 -> 0 | K145: =INF_FC_EUR!S146 -> 0 | ... BQ145: =INF_FC_EUR!BY146 -> 0
A146: =IF(OR(B146=0,B146=""),"",B146&IF(COUNTIF(B$11:$B146,B146)>1,COUNTIF(B$11:$B146,B146),"")) -> All Business Types | B146: =INF_FC_EUR!J147 -> All Business Types | D146: =INF_FC_EUR!L147 -> 0 | E146: =INF_FC_EUR!M147 -> 0 | F146: =INF_FC_EUR!N147 -> 0 | G146: =INF_FC_EUR!O147 -> 0 | H146: =INF_FC_EUR!P147 -> 0 | I146: =INF_FC_EUR!Q147 -> 0 | J146: =INF_FC_EUR!R147 -> 0 | K146: =INF_FC_EUR!S147 -> 0 | ... BQ146: =INF_FC_EUR!BY147 -> 0
A147: =IF(OR(B147=0,B147=""),"",B147&IF(COUNTIF(B$11:$B147,B147)>1,COUNTIF(B$11:$B147,B147),"")) -> Papers | B147: =INF_FC_EUR!J148 -> Papers | D147: =INF_FC_EUR!L148 -> 0 | E147: =INF_FC_EUR!M148 -> 0 | F147: =INF_FC_EUR!N148 -> 0 | G147: =INF_FC_EUR!O148 -> 0 | H147: =INF_FC_EUR!P148 -> 0 | I147: =INF_FC_EUR!Q148 -> 0 | J147: =INF_FC_EUR!R148 -> 0 | K147: =INF_FC_EUR!S148 -> 0 | ... BQ147: =INF_FC_EUR!BY148 -> 0
A148: =IF(OR(B148=0,B148=""),"",B148&IF(COUNTIF(B$11:$B148,B148)>1,COUNTIF(B$11:$B148,B148),"")) -> Plastics | B148: =INF_FC_EUR!J149 -> Plastics | D148: =INF_FC_EUR!L149 -> 0 | E148: =INF_FC_EUR!M149 -> 0 | F148: =INF_FC_EUR!N149 -> 0 | G148: =INF_FC_EUR!O149 -> 0 | H148: =INF_FC_EUR!P149 -> 0 | I148: =INF_FC_EUR!Q149 -> 0 | J148: =INF_FC_EUR!R149 -> 0 | K148: =INF_FC_EUR!S149 -> 0 | ... BQ148: =INF_FC_EUR!BY149 -> 0
A149: =IF(OR(B149=0,B149=""),"",B149&IF(COUNTIF(B$11:$B149,B149)>1,COUNTIF(B$11:$B149,B149),"")) -> Refuse Derived Fuels | B149: =INF_FC_EUR!J150 -> Refuse Derived Fuels | D149: =INF_FC_EUR!L150 -> 0 | E149: =INF_FC_EUR!M150 -> 0 | F149: =INF_FC_EUR!N150 -> 0 | G149: =INF_FC_EUR!O150 -> 0 | H149: =INF_FC_EUR!P150 -> 0 | I149: =INF_FC_EUR!Q150 -> 0 | J149: =INF_FC_EUR!R150 -> 0 | K149: =INF_FC_EUR!S150 -> 0 | ... BQ149: =INF_FC_EUR!BY150 -> 0
A150: =IF(OR(B150=0,B150=""),"",B150&IF(COUNTIF(B$11:$B150,B150)>1,COUNTIF(B$11:$B150,B150),"")) -> Metals | B150: =INF_FC_EUR!J151 -> Metals | D150: =INF_FC_EUR!L151 -> 0 | E150: =INF_FC_EUR!M151 -> 0 | F150: =INF_FC_EUR!N151 -> 0 | G150: =INF_FC_EUR!O151 -> 0 | H150: =INF_FC_EUR!P151 -> 0 | I150: =INF_FC_EUR!Q151 -> 0 | J150: =INF_FC_EUR!R151 -> 0 | K150: =INF_FC_EUR!S151 -> 0 | ... BQ150: =INF_FC_EUR!BY151 -> 0
A151: =IF(OR(B151=0,B151=""),"",B151&IF(COUNTIF(B$11:$B151,B151)>1,COUNTIF(B$11:$B151,B151),"")) -> Glass | B151: =INF_FC_EUR!J152 -> Glass | D151: =INF_FC_EUR!L152 -> 0 | E151: =INF_FC_EUR!M152 -> 0 | F151: =INF_FC_EUR!N152 -> 0 | G151: =INF_FC_EUR!O152 -> 0 | H151: =INF_FC_EUR!P152 -> 0 | I151: =INF_FC_EUR!Q152 -> 0 | J151: =INF_FC_EUR!R152 -> 0 | K151: =INF_FC_EUR!S152 -> 0 | ... BQ151: =INF_FC_EUR!BY152 -> 0
A152: =IF(OR(B152=0,B152=""),"",B152&IF(COUNTIF(B$11:$B152,B152)>1,COUNTIF(B$11:$B152,B152),"")) -> Wood | B152: =INF_FC_EUR!J153 -> Wood | D152: =INF_FC_EUR!L153 -> 0 | E152: =INF_FC_EUR!M153 -> 0 | F152: =INF_FC_EUR!N153 -> 0 | G152: =INF_FC_EUR!O153 -> 0 | H152: =INF_FC_EUR!P153 -> 0 | I152: =INF_FC_EUR!Q153 -> 0 | J152: =INF_FC_EUR!R153 -> 0 | K152: =INF_FC_EUR!S153 -> 0 | ... BQ152: =INF_FC_EUR!BY153 -> 0
A153: =IF(OR(B153=0,B153=""),"",B153&IF(COUNTIF(B$11:$B153,B153)>1,COUNTIF(B$11:$B153,B153),"")) -> Final Goods | B153: =INF_FC_EUR!J154 -> Final Goods | D153: =INF_FC_EUR!L154 -> 0 | E153: =INF_FC_EUR!M154 -> 0 | F153: =INF_FC_EUR!N154 -> 0 | G153: =INF_FC_EUR!O154 -> 0 | H153: =INF_FC_EUR!P154 -> 0 | I153: =INF_FC_EUR!Q154 -> 0 | J153: =INF_FC_EUR!R154 -> 0 | K153: =INF_FC_EUR!S154 -> 0 | ... BQ153: =INF_FC_EUR!BY154 -> 0
A154: =IF(OR(B154=0,B154=""),"",B154&IF(COUNTIF(B$11:$B154,B154)>1,COUNTIF(B$11:$B154,B154),"")) -> Compound | B154: =INF_FC_EUR!J155 -> Compound | D154: =INF_FC_EUR!L155 -> 0 | E154: =INF_FC_EUR!M155 -> 0 | F154: =INF_FC_EUR!N155 -> 0 | G154: =INF_FC_EUR!O155 -> 0 | H154: =INF_FC_EUR!P155 -> 0 | I154: =INF_FC_EUR!Q155 -> 0 | J154: =INF_FC_EUR!R155 -> 0 | K154: =INF_FC_EUR!S155 -> 0 | ... BQ154: =INF_FC_EUR!BY155 -> 0
A155: =IF(OR(B155=0,B155=""),"",B155&IF(COUNTIF(B$11:$B155,B155)>1,COUNTIF(B$11:$B155,B155),"")) -> Waste | B155: =INF_FC_EUR!J156 -> Waste | D155: =INF_FC_EUR!L156 -> 0 | E155: =INF_FC_EUR!M156 -> 0 | F155: =INF_FC_EUR!N156 -> 0 | G155: =INF_FC_EUR!O156 -> 0 | H155: =INF_FC_EUR!P156 -> 0 | I155: =INF_FC_EUR!Q156 -> 0 | J155: =INF_FC_EUR!R156 -> 0 | K155: =INF_FC_EUR!S156 -> 0 | ... BQ155: =INF_FC_EUR!BY156 -> 0
... A330: =IF(OR(B330=0,B330=""),"",B330&IF(COUNTIF(B$11:$B330,B330)>1,COUNTIF(B$11:$B330,B330),"")) | B330: =INF_FC_EUR!J331 -> 0 | D330: =INF_FC_EUR!L331 -> 0 | E330: =INF_FC_EUR!M331 -> 0 | F330: =INF_FC_EUR!N331 -> 0 | G330: =INF_FC_EUR!O331 -> 0 | H330: =INF_FC_EUR!P331 -> 0 | I330: =INF_FC_EUR!Q331 -> 0 | J330: =INF_FC_EUR!R331 -> 0 | K330: =INF_FC_EUR!S331 -> 0 | ... BQ330: =INF_FC_EUR!BY331 -> 0

Sheet BusPlanLocation
C6: =IF(START!$C$18="EUR",1,IF($C$9="EUR",1,START!$E$18)) -> 1
C7: =START!$C$10 -> 166101 Bornova | D7: Previous year | F7: Forecast | I7: Business Plan Periods
C8: Registration currency: | D8: =START!C14-1&"-12 YTD" -> 2020-12 YTD | F8: =START!C14&"-12 YTD" -> 2021-12 YTD | I8: =START!C14 -> 2021 | K8: =I8+1 -> 2022 | M8: =K8+1 -> 2023 | O8: =M8+1 -> 2024 | Q8: =O8+1 -> 2025 | S8: =Q8+1 -> 2026
C9: EUR | D9: Actual | F9: Actual | G9: Adaption | I9: Business Plan | K9: Business Plan | M9: Business Plan | O9: Business Plan | Q9: Business Plan | S9: Business Plan
B10: Acc | C10: Name | D10: ="in 1.000 "&$C$9 -> in 1.000 EUR | E10: % | F10: ="in 1.000 "&$C$9 -> in 1.000 EUR | G10: ="in 1.000 "&$C$9 -> in 1.000 EUR | H10: % | I10: ="in 1.000 "&$C$9 -> in 1.000 EUR | J10: % | K10: ="in 1.000 "&$C$9 -> in 1.000 EUR | L10: % | M10: ="in 1.000 "&$C$9 -> in 1.000 EUR | N10: % | O10: ="in 1.000 "&$C$9 -> in 1.000 EUR | P10: % | Q10: ="in 1.000 "&$C$9 -> in 1.000 EUR | R10: % | S10: ="in 1.000 "&$C$9 -> in 1.000 EUR | T10: %
A11: =AA11 -> M105 | B11: M105 | C11: Sales (gross) - Core Business ext. | D11: =VLOOKUP($AA11,Calc_INF_PrevYearEUR!$A$11:$BQ$330,HLOOKUP($C$7,Calc_INF_PrevYearEUR!$E$5:$BQ$6,2,0),0)*IF($C$9="EUR",1,START!$E$18) -> #N/A | E11: =IF(D11=0,0,D11/D$42) -> #N/A | F11: =IF(F13<>0,VLOOKUP($AA11,Calc_INF_FC_EUR!$A$11:$BQ$330,HLOOKUP($C$7,Calc_INF_FC_EUR!$E$5:$BQ$6,2,0),0)*IF($C$9="EUR",1,START!$E$18)+(VLOOKUP($AA11,Calc_INF_FC_EUR!$A$11:$BQ$330,HLOOKUP($C$7,Calc_INF_FC_EUR!$E$5:$BQ$6,2,0),0)*IF($C$9="EUR",1,START!$E$18))/F13*G13,0) -> #N/A | G11: =F11-VLOOKUP($AA11,Calc_INF_FC_EUR!$A$11:$BQ$330,HLOOKUP($C$7,Calc_INF_FC_EUR!$E$5:$BQ$6,2,0),0)*IF($C$9="EUR",1,START!$E$18) -> #N/A | I11: =SUMIFS(SalesReport!$R:$R,SalesReport!$AF:$AF,$AB11,SalesReport!$A:$A,I$8,SalesReport!$B:$B,BusPlanLocation!$C$7)*IF($C$9="EUR",1,START!$E$18)/1000 -> #REF! | J11: =IF(I11=0,0,I11/I$42) -> #REF! | K11: =SUMIFS(SalesReport!$R:$R,SalesReport!$AF:$AF,$AB11,SalesReport!$A:$A,K$8,SalesReport!$B:$B,BusPlanLocation!$C$7)*IF($C$9="EUR",1,START!$E$18)/1000 -> 0 | L11: =IF(K11=0,0,K11/K$42) -> 0 | M11: =SUMIFS(SalesReport!$R:$R,SalesReport!$AF:$AF,$AB11,SalesReport!$A:$A,M$8,SalesReport!$B:$B,BusPlanLocation!$C$7)*IF($C$9="EUR",1,START!$E$18)/1000 -> 0 | N11: =IF(M11=0,0,M11/M$42) -> 0 | O11: =SUMIFS(SalesReport!$R:$R,SalesReport!$AF:$AF,$AB11,SalesReport!$A:$A,O$8,SalesReport!$B:$B,BusPlanLocation!$C$7)*IF($C$9="EUR",1,START!$E$18)/1000 -> 0 | P11: =IF(O11=0,0,O11/O$42) -> 0 | Q11: =SUMIFS(SalesReport!$R:$R,SalesReport!$AF:$AF,$AB11,SalesReport!$A:$A,Q$8,SalesReport!$B:$B,BusPlanLocation!$C$7)*IF($C$9="EUR",1,START!$E$18)/1000 -> 0 | R11: =IF(Q11=0,0,Q11/Q$42) -> 0 | S11: =SUMIFS(SalesReport!$R:$R,SalesReport!$AF:$AF,$AB11,SalesReport!$A:$A,S$8,SalesReport!$B:$B,BusPlanLocation!$C$7)*IF($C$9="EUR",1,START!$E$18)/1000 -> 0 | T11: =IF(S11=0,0,S11/S$42) -> 0 | AA11: =IF(OR(B11=0,B11=""),"",B11&IF(COUNTIF(B$11:$B11,B11)>1,COUNTIF(B$11:$B11,B11),"")) -> M105 | AB11: Collectionext
A12: =AA12 -> M106 | B12: M106 | C12: Sales (gross) - Core Business affil. | D12: =VLOOKUP($AA12,Calc_INF_PrevYearEUR!$A$11:$BQ$330,HLOOKUP($C$7,Calc_INF_PrevYearEUR!$E$5:$BQ$6,2,0),0)*IF($C$9="EUR",1,START!$E$18) -> #N/A | E12: =IF(D12=0,0,D12/D$42) -> #N/A | F12: =IF(F13<>0,VLOOKUP($AA12,Calc_INF_FC_EUR!$A$11:$BQ$330,HLOOKUP($C$7,Calc_INF_FC_EUR!$E$5:$BQ$6,2,0),0)*IF($C$9="EUR",1,START!$E$18)+(VLOOKUP($AA12,Calc_INF_FC_EUR!$A$11:$BQ$330,HLOOKUP($C$7,Calc_INF_FC_EUR!$E$5:$BQ$6,2,0),0)*IF($C$9="EUR",1,START!$E$18))/F13*G13,0) -> #N/A | G12: =F12-VLOOKUP($AA12,Calc_INF_FC_EUR!$A$11:$BQ$330,HLOOKUP($C$7,Calc_INF_FC_EUR!$E$5:$BQ$6,2,0),0)*IF($C$9="EUR",1,START!$E$18) -> #N/A | I12: =SUMIFS(SalesReport!$R:$R,SalesReport!$AF:$AF,$AB12,SalesReport!$A:$A,I$8,SalesReport!$B:$B,BusPlanLocation!$C$7)*IF($C$9="EUR",1,START!$E$18)/1000 -> 0 | J12: =IF(I12=0,0,I12/I$42) -> 0 | K12: =SUMIFS(SalesReport!$R:$R,SalesReport!$AF:$AF,$AB12,SalesReport!$A:$A,K$8,SalesReport!$B:$B,BusPlanLocation!$C$7)*IF($C$9="EUR",1,START!$E$18)/1000 -> 0 | L12: =IF(K12=0,0,K12/K$42) -> 0 | M12: =SUMIFS(SalesReport!$R:$R,SalesReport!$AF:$AF,$AB12,SalesReport!$A:$A,M$8,SalesReport!$B:$B,BusPlanLocation!$C$7)*IF($C$9="EUR",1,START!$E$18)/1000 -> 0 | N12: =IF(M12=0,0,M12/M$42) -> 0 | O12: =SUMIFS(SalesReport!$R:$R,SalesReport!$AF:$AF,$AB12,SalesReport!$A:$A,O$8,SalesReport!$B:$B,BusPlanLocation!$C$7)*IF($C$9="EUR",1,START!$E$18)/1000 -> 0 | P12: =IF(O12=0,0,O12/O$42) -> 0 | Q12: =SUMIFS(SalesReport!$R:$R,SalesReport!$AF:$AF,$AB12,SalesReport!$A:$A,Q$8,SalesReport!$B:$B,BusPlanLocation!$C$7)*IF($C$9="EUR",1,START!$E$18)/1000 -> 0 | R12: =IF(Q12=0,0,Q12/Q$42) -> 0 | S12: =SUMIFS(SalesReport!$R:$R,SalesReport!$AF:$AF,$AB12,SalesReport!$A:$A,S$8,SalesReport!$B:$B,BusPlanLocation!$C$7)*IF($C$9="EUR",1,START!$E$18)/1000 -> 0 | T12: =IF(S12=0,0,S12/S$42) -> 0 | AA12: =IF(OR(B12=0,B12=""),"",B12&IF(COUNTIF(B$11:$B12,B12)>1,COUNTIF(B$11:$B12,B12),"")) -> M106 | AB12: Collectionaff
A13: =AA13 -> M109 | B13: M109 | C13: Total Sales (gross) - Core Business | D13: =VLOOKUP($AA13,Calc_INF_PrevYearEUR!$A$11:$BQ$330,HLOOKUP($C$7,Calc_INF_PrevYearEUR!$E$5:$BQ$6,2,0),0)*IF($C$9="EUR",1,START!$E$18) -> #N/A | E13: =IF(D13=0,0,D13/D$42) -> #N/A | F13: =VLOOKUP($AA13,Calc_INF_FC_EUR!$A$11:$BQ$330,HLOOKUP($C$7,Calc_INF_FC_EUR!$E$5:$BQ$6,2,0),0)*IF($C$9="EUR",1,START!$E$18)+G13 -> #N/A | G13: =IF(AND($G$155<>0,$G$232<>0),((VLOOKUP("Collection",Calc_INF_FC_EUR!$A$11:$BQ$330,HLOOKUP($C$7,Calc_INF_FC_EUR!$E$5:$BQ$6,2,0),0)*IF($C$9="EUR",1,START!$E$18)+$G$155)*(VLOOKUP($AA232,Calc_INF_FC_EUR!$A$11:$BQ$330,HLOOKUP($C$7,Calc_INF_FC_EUR!$E$5:$BQ$6,2,0),0)*IF($C$9="EUR",1,START!$E$18)+$G$232))/1000-VLOOKUP($AA13,Calc_INF_FC_EUR!$A$11:$BQ$330,HLOOKUP($C$7,Calc_INF_FC_EUR!$E$5:$BQ$6,2,0),0)*IF($C$9="EUR",1,START!$E$18),IF(OR($G$155<>0,$G$232<>0),(IF($G$155<>0,$G$155,VLOOKUP($AA155,Calc_INF_FC_EUR!$A$11:$BQ$330,HLOOKUP($C$7,Calc_INF_FC_EUR!$E$5:$BQ$6,2,0),0)*IF($C$9="EUR",1,START!$E$18))*IF($G$232<>0,$G$232,VLOOKUP($AA232,Calc_INF_FC_EUR!$A$11:$BQ$330,HLOOKUP($C$7,Calc_INF_FC_EUR!$E$5:$BQ$6,2,0),0)*IF($C$9="EUR",1,START!$E$18)))/1000,0)) -> 0 | I13: =I11+I12 -> #REF! | J13: =IF(I13=0,0,I13/I$42) -> #REF! | K13: =K11+K12 -> 0 | L13: =IF(K13=0,0,K13/K$42) -> 0 | M13: =M11+M12 -> 0 | N13: =IF(M13=0,0,M13/M$42) -> 0 | O13: =O11+O12 -> 0 | P13: =IF(O13=0,0,O13/O$42) -> 0 | Q13: =Q11+Q12 -> 0 | R13: =IF(Q13=0,0,Q13/Q$42) -> 0 | S13: =S11+S12 -> 0 | T13: =IF(S13=0,0,S13/S$42) -> 0 | AA13: =IF(OR(B13=0,B13=""),"",B13&IF(COUNTIF(B$11:$B13,B13)>1,COUNTIF(B$11:$B13,B13),"")) -> M109
A14: =AA14 -> M115 | B14: M115 | C14: Customer Bonus | D14: =VLOOKUP($AA14,Calc_INF_PrevYearEUR!$A$11:$BQ$330,HLOOKUP($C$7,Calc_INF_PrevYearEUR!$E$5:$BQ$6,2,0),0)*IF($C$9="EUR",1,START!$E$18) -> #N/A | E14: =IF(D14=0,0,D14/D$42) -> #N/A | F14: =VLOOKUP($AA14,Calc_INF_FC_EUR!$A$11:$BQ$330,HLOOKUP($C$7,Calc_INF_FC_EUR!$E$5:$BQ$6,2,0),0)*IF($C$9="EUR",1,START!$E$18)+G14 -> #N/A | J14: =IF(I14=0,0,I14/I$42) -> 0 | L14: =IF(K14=0,0,K14/K$42) -> 0 | N14: =IF(M14=0,0,M14/M$42) -> 0 | P14: =IF(O14=0,0,O14/O$42) -> 0 | R14: =IF(Q14=0,0,Q14/Q$42) -> 0 | T14: =IF(S14=0,0,S14/S$42) -> 0 | AA14: =IF(OR(B14=0,B14=""),"",B14&IF(COUNTIF(B$11:$B14,B14)>1,COUNTIF(B$11:$B14,B14),"")) -> M115
A15: =AA15 -> M116 | B15: M116 | C15: Customer Bonus affil. | D15: =VLOOKUP($AA15,Calc_INF_PrevYearEUR!$A$11:$BQ$330,HLOOKUP($C$7,Calc_INF_PrevYearEUR!$E$5:$BQ$6,2,0),0)*IF($C$9="EUR",1,START!$E$18) -> #N/A | E15: =IF(D15=0,0,D15/D$42) -> #N/A | F15: =VLOOKUP($AA15,Calc_INF_FC_EUR!$A$11:$BQ$330,HLOOKUP($C$7,Calc_INF_FC_EUR!$E$5:$BQ$6,2,0),0)*IF($C$9="EUR",1,START!$E$18)+G15 -> #N/A | J15: =IF(I15=0,0,I15/I$42) -> 0 | L15: =IF(K15=0,0,K15/K$42) -> 0 | N15: =IF(M15=0,0,M15/M$42) -> 0 | P15: =IF(O15=0,0,O15/O$42) -> 0 | R15: =IF(Q15=0,0,Q15/Q$42) -> 0 | T15: =IF(S15=0,0,S15/S$42) -> 0 | AA15: =IF(OR(B15=0,B15=""),"",B15&IF(COUNTIF(B$11:$B15,B15)>1,COUNTIF(B$11:$B15,B15),"")) -> M116
A16: =AA16 -> M120 | B16: M120 | C16: Claims | D16: =VLOOKUP($AA16,Calc_INF_PrevYearEUR!$A$11:$BQ$330,HLOOKUP($C$7,Calc_INF_PrevYearEUR!$E$5:$BQ$6,2,0),0)*IF($C$9="EUR",1,START!$E$18) -> #N/A | E16: =IF(D16=0,0,D16/D$42) -> #N/A | F16: =VLOOKUP($AA16,Calc_INF_FC_EUR!$A$11:$BQ$330,HLOOKUP($C$7,Calc_INF_FC_EUR!$E$5:$BQ$6,2,0),0)*IF($C$9="EUR",1,START!$E$18)+G16 -> #N/A | J16: =IF(I16=0,0,I16/I$42) -> 0 | L16: =IF(K16=0,0,K16/K$42) -> 0 | N16: =IF(M16=0,0,M16/M$42) -> 0 | P16: =IF(O16=0,0,O16/O$42) -> 0 | R16: =IF(Q16=0,0,Q16/Q$42) -> 0 | T16: =IF(S16=0,0,S16/S$42) -> 0 | AA16: =IF(OR(B16=0,B16=""),"",B16&IF(COUNTIF(B$11:$B16,B16)>1,COUNTIF(B$11:$B16,B16),"")) -> M120
A17: =AA17 -> M121 | B17: M121 | C17: Claims affil. | D17: =VLOOKUP($AA17,Calc_INF_PrevYearEUR!$A$11:$BQ$330,HLOOKUP($C$7,Calc_INF_PrevYearEUR!$E$5:$BQ$6,2,0),0)*IF($C$9="EUR",1,START!$E$18) -> #N/A | E17: =IF(D17=0,0,D17/D$42) -> #N/A | F17: =VLOOKUP($AA17,Calc_INF_FC_EUR!$A$11:$BQ$330,HLOOKUP($C$7,Calc_INF_FC_EUR!$E$5:$BQ$6,2,0),0)*IF($C$9="EUR",1,START!$E$18)+G17 -> #N/A | J17: =IF(I17=0,0,I17/I$42) -> 0 | L17: =IF(K17=0,0,K17/K$42) -> 0 | N17: =IF(M17=0,0,M17/M$42) -> 0 | P17: =IF(O17=0,0,O17/O$42) -> 0 | R17: =IF(Q17=0,0,Q17/Q$42) -> 0 | T17: =IF(S17=0,0,S17/S$42) -> 0 | AA17: =IF(OR(B17=0,B17=""),"",B17&IF(COUNTIF(B$11:$B17,B17)>1,COUNTIF(B$11:$B17,B17),"")) -> M121
A18: =AA18 -> M125 | B18: M125 | C18: Discount | D18: =VLOOKUP($AA18,Calc_INF_PrevYearEUR!$A$11:$BQ$330,HLOOKUP($C$7,Calc_INF_PrevYearEUR!$E$5:$BQ$6,2,0),0)*IF($C$9="EUR",1,START!$E$18) -> #N/A | E18: =IF(D18=0,0,D18/D$42) -> #N/A | F18: =VLOOKUP($AA18,Calc_INF_FC_EUR!$A$11:$BQ$330,HLOOKUP($C$7,Calc_INF_FC_EUR!$E$5:$BQ$6,2,0),0)*IF($C$9="EUR",1,START!$E$18)+G18 -> #N/A | J18: =IF(I18=0,0,I18/I$42) -> 0 | L18: =IF(K18=0,0,K18/K$42) -> 0 | N18: =IF(M18=0,0,M18/M$42) -> 0 | P18: =IF(O18=0,0,O18/O$42) -> 0 | R18: =IF(Q18=0,0,Q18/Q$42) -> 0 | T18: =IF(S18=0,0,S18/S$42) -> 0 | AA18: =IF(OR(B18=0,B18=""),"",B18&IF(COUNTIF(B$11:$B18,B18)>1,COUNTIF(B$11:$B18,B18),"")) -> M125
A19: =AA19 -> M126 | B19: M126 | C19: Discount affil. | D19: =VLOOKUP($AA19,Calc_INF_PrevYearEUR!$A$11:$BQ$330,HLOOKUP($C$7,Calc_INF_PrevYearEUR!$E$5:$BQ$6,2,0),0)*IF($C$9="EUR",1,START!$E$18) -> #N/A | E19: =IF(D19=0,0,D19/D$42) -> #N/A | F19: =VLOOKUP($AA19,Calc_INF_FC_EUR!$A$11:$BQ$330,HLOOKUP($C$7,Calc_INF_FC_EUR!$E$5:$BQ$6,2,0),0)*IF($C$9="EUR",1,START!$E$18)+G19 -> #N/A | J19: =IF(I19=0,0,I19/I$42) -> 0 | L19: =IF(K19=0,0,K19/K$42) -> 0 | N19: =IF(M19=0,0,M19/M$42) -> 0 | P19: =IF(O19=0,0,O19/O$42) -> 0 | R19: =IF(Q19=0,0,Q19/Q$42) -> 0 | T19: =IF(S19=0,0,S19/S$42) -> 0 | AA19: =IF(OR(B19=0,B19=""),"",B19&IF(COUNTIF(B$11:$B19,B19)>1,COUNTIF(B$11:$B19,B19),"")) -> M126
A20: =AA20 -> M130 | B20: M130 | C20: Freight refund | D20: =VLOOKUP($AA20,Calc_INF_PrevYearEUR!$A$11:$BQ$330,HLOOKUP($C$7,Calc_INF_PrevYearEUR!$E$5:$BQ$6,2,0),0)*IF($C$9="EUR",1,START!$E$18) -> #N/A | E20: =IF(D20=0,0,D20/D$42) -> #N/A | F20: =VLOOKUP($AA20,Calc_INF_FC_EUR!$A$11:$BQ$330,HLOOKUP($C$7,Calc_INF_FC_EUR!$E$5:$BQ$6,2,0),0)*IF($C$9="EUR",1,START!$E$18)+G20 -> #N/A | J20: =IF(I20=0,0,I20/I$42) -> 0 | L20: =IF(K20=0,0,K20/K$42) -> 0 | N20: =IF(M20=0,0,M20/M$42) -> 0 | P20: =IF(O20=0,0,O20/O$42) -> 0 | R20: =IF(Q20=0,0,Q20/Q$42) -> 0 | T20: =IF(S20=0,0,S20/S$42) -> 0 | AA20: =IF(OR(B20=0,B20=""),"",B20&IF(COUNTIF(B$11:$B20,B20)>1,COUNTIF(B$11:$B20,B20),"")) -> M130
A21: =AA21 -> M131 | B21: M131 | C21: Freight refund affil. | D21: =VLOOKUP($AA21,Calc_INF_PrevYearEUR!$A$11:$BQ$330,HLOOKUP($C$7,Calc_INF_PrevYearEUR!$E$5:$BQ$6,2,0),0)*IF($C$9="EUR",1,START!$E$18) -> #N/A | E21: =IF(D21=0,0,D21/D$42) -> #N/A | F21: =VLOOKUP($AA21,Calc_INF_FC_EUR!$A$11:$BQ$330,HLOOKUP($C$7,Calc_INF_FC_EUR!$E$5:$BQ$6,2,0),0)*IF($C$9="EUR",1,START!$E$18)+G21 -> #N/A | J21: =IF(I21=0,0,I21/I$42) -> 0 | L21: =IF(K21=0,0,K21/K$42) -> 0 | N21: =IF(M21=0,0,M21/M$42) -> 0 | P21: =IF(O21=0,0,O21/O$42) -> 0 | R21: =IF(Q21=0,0,Q21/Q$42) -> 0 | T21: =IF(S21=0,0,S21/S$42) -> 0 | AA21: =IF(OR(B21=0,B21=""),"",B21&IF(COUNTIF(B$11:$B21,B21)>1,COUNTIF(B$11:$B21,B21),"")) -> M131
A22: =AA22 -> M139 | B22: M139 | C22: Reduction in Sales - Core Business | D22: =VLOOKUP($AA22,Calc_INF_PrevYearEUR!$A$11:$BQ$330,HLOOKUP($C$7,Calc_INF_PrevYearEUR!$E$5:$BQ$6,2,0),0)*IF($C$9="EUR",1,START!$E$18) -> #N/A | E22: =IF(D22=0,0,D22/D$42) -> #N/A | F22: =VLOOKUP($AA22,Calc_INF_FC_EUR!$A$11:$BQ$330,HLOOKUP($C$7,Calc_INF_FC_EUR!$E$5:$BQ$6,2,0),0)*IF($C$9="EUR",1,START!$E$18)+G22 -> #N/A | G22: =SUM(G14:G21) -> 0 | I22: =SUM(I14:I21) -> 0 | J22: =IF(I22=0,0,I22/I$42) -> 0 | K22: =SUM(K14:K21) -> 0 | L22: =IF(K22=0,0,K22/K$42) -> 0 | M22: =SUM(M14:M21) -> 0 | N22: =IF(M22=0,0,M22/M$42) -> 0 | O22: =SUM(O14:O21) -> 0 | P22: =IF(O22=0,0,O22/O$42) -> 0 | Q22: =SUM(Q14:Q21) -> 0 | R22: =IF(Q22=0,0,Q22/Q$42) -> 0 | S22: =SUM(S14:S21) -> 0 | T22: =IF(S22=0,0,S22/S$42) -> 0 | AA22: =IF(OR(B22=0,B22=""),"",B22&IF(COUNTIF(B$11:$B22,B22)>1,COUNTIF(B$11:$B22,B22),"")) -> M139
A23: =AA23 -> M145 | B23: M145 | C23: Revenues from trade goods ext. | D23: =VLOOKUP($AA23,Calc_INF_PrevYearEUR!$A$11:$BQ$330,HLOOKUP($C$7,Calc_INF_PrevYearEUR!$E$5:$BQ$6,2,0),0)*IF($C$9="EUR",1,START!$E$18) -> #N/A | E23: =IF(D23=0,0,D23/D$42) -> #N/A | F23: =VLOOKUP($AA23,Calc_INF_FC_EUR!$A$11:$BQ$330,HLOOKUP($C$7,Calc_INF_FC_EUR!$E$5:$BQ$6,2,0),0)*IF($C$9="EUR",1,START!$E$18)+G23 -> #N/A | I23: =SUMIFS(SalesReport!$R:$R,SalesReport!$AF:$AF,$AB23,SalesReport!$A:$A,I$8,SalesReport!$B:$B,BusPlanLocation!$C$7)*IF($C$9="EUR",1,START!$E$18)/1000 -> 0 | J23: =IF(I23=0,0,I23/I$42) -> 0 | K23: =SUMIFS(SalesReport!$R:$R,SalesReport!$AF:$AF,$AB23,SalesReport!$A:$A,K$8,SalesReport!$B:$B,BusPlanLocation!$C$7)*IF($C$9="EUR",1,START!$E$18)/1000 -> 0 | L23: =IF(K23=0,0,K23/K$42) -> 0 | M23: =SUMIFS(SalesReport!$R:$R,SalesReport!$AF:$AF,$AB23,SalesReport!$A:$A,M$8,SalesReport!$B:$B,BusPlanLocation!$C$7)*IF($C$9="EUR",1,START!$E$18)/1000 -> 0 | N23: =IF(M23=0,0,M23/M$42) -> 0 | O23: =SUMIFS(SalesReport!$R:$R,SalesReport!$AF:$AF,$AB23,SalesReport!$A:$A,O$8,SalesReport!$B:$B,BusPlanLocation!$C$7)*IF($C$9="EUR",1,START!$E$18)/1000 -> 0 | P23: =IF(O23=0,0,O23/O$42) -> 0 | Q23: =SUMIFS(SalesReport!$R:$R,SalesReport!$AF:$AF,$AB23,SalesReport!$A:$A,Q$8,SalesReport!$B:$B,BusPlanLocation!$C$7)*IF($C$9="EUR",1,START!$E$18)/1000 -> 0 | R23: =IF(Q23=0,0,Q23/Q$42) -> 0 | S23: =SUMIFS(SalesReport!$R:$R,SalesReport!$AF:$AF,$AB23,SalesReport!$A:$A,S$8,SalesReport!$B:$B,BusPlanLocation!$C$7)*IF($C$9="EUR",1,START!$E$18)/1000 -> 0 | T23: =IF(S23=0,0,S23/S$42) -> 0 | AA23: =IF(OR(B23=0,B23=""),"",B23&IF(COUNTIF(B$11:$B23,B23)>1,COUNTIF(B$11:$B23,B23),"")) -> M145 | AB23: Tradeext
A24: =AA24 -> M146 | B24: M146 | C24: Revenues from trade goods affil. | D24: =VLOOKUP($AA24,Calc_INF_PrevYearEUR!$A$11:$BQ$330,HLOOKUP($C$7,Calc_INF_PrevYearEUR!$E$5:$BQ$6,2,0),0)*IF($C$9="EUR",1,START!$E$18) -> #N/A | E24: =IF(D24=0,0,D24/D$42) -> #N/A | F24: =VLOOKUP($AA24,Calc_INF_FC_EUR!$A$11:$BQ$330,HLOOKUP($C$7,Calc_INF_FC_EUR!$E$5:$BQ$6,2,0),0)*IF($C$9="EUR",1,START!$E$18)+G24 -> #N/A | I24: =SUMIFS(SalesReport!$R:$R,SalesReport!$AF:$AF,$AB24,SalesReport!$A:$A,I$8,SalesReport!$B:$B,BusPlanLocation!$C$7)*IF($C$9="EUR",1,START!$E$18)/1000 -> 0 | J24: =IF(I24=0,0,I24/I$42) -> 0 | K24: =SUMIFS(SalesReport!$R:$R,SalesReport!$AF:$AF,$AB24,SalesReport!$A:$A,K$8,SalesReport!$B:$B,BusPlanLocation!$C$7)*IF($C$9="EUR",1,START!$E$18)/1000 -> 0 | L24: =IF(K24=0,0,K24/K$42) -> 0 | M24: =SUMIFS(SalesReport!$R:$R,SalesReport!$AF:$AF,$AB24,SalesReport!$A:$A,M$8,SalesReport!$B:$B,BusPlanLocation!$C$7)*IF($C$9="EUR",1,START!$E$18)/1000 -> 0 | N24: =IF(M24=0,0,M24/M$42) -> 0 | O24: =SUMIFS(SalesReport!$R:$R,SalesReport!$AF:$AF,$AB24,SalesReport!$A:$A,O$8,SalesReport!$B:$B,BusPlanLocation!$C$7)*IF($C$9="EUR",1,START!$E$18)/1000 -> 0 | P24: =IF(O24=0,0,O24/O$42) -> 0 | Q24: =SUMIFS(SalesReport!$R:$R,SalesReport!$AF:$AF,$AB24,SalesReport!$A:$A,Q$8,SalesReport!$B:$B,BusPlanLocation!$C$7)*IF($C$9="EUR",1,START!$E$18)/1000 -> 0 | R24: =IF(Q24=0,0,Q24/Q$42) -> 0 | S24: =SUMIFS(SalesReport!$R:$R,SalesReport!$AF:$AF,$AB24,SalesReport!$A:$A,S$8,SalesReport!$B:$B,BusPlanLocation!$C$7)*IF($C$9="EUR",1,START!$E$18)/1000 -> 0 | T24: =IF(S24=0,0,S24/S$42) -> 0 | AA24: =IF(OR(B24=0,B24=""),"",B24&IF(COUNTIF(B$11:$B24,B24)>1,COUNTIF(B$11:$B24,B24),"")) -> M146 | AB24: Tradeaff
A25: =AA25 -> M149 | B25: M149 | C25: Sales from trade goods (net) | D25: =VLOOKUP($AA25,Calc_INF_PrevYearEUR!$A$11:$BQ$330,HLOOKUP($C$7,Calc_INF_PrevYearEUR!$E$5:$BQ$6,2,0),0)*IF($C$9="EUR",1,START!$E$18) -> #N/A | E25: =IF(D25=0,0,D25/D$42) -> #N/A | F25: =VLOOKUP($AA25,Calc_INF_FC_EUR!$A$11:$BQ$330,HLOOKUP($C$7,Calc_INF_FC_EUR!$E$5:$BQ$6,2,0),0)*IF($C$9="EUR",1,START!$E$18)+G25 -> #N/A | G25: =+G24+G23 -> 0 | I25: =+I24+I23 -> 0 | J25: =IF(I25=0,0,I25/I$42) -> 0 | K25: =+K24+K23 -> 0 | L25: =IF(K25=0,0,K25/K$42) -> 0 | M25: =+M24+M23 -> 0 | N25: =IF(M25=0,0,M25/M$42) -> 0 | O25: =+O24+O23 -> 0 | P25: =IF(O25=0,0,O25/O$42) -> 0 | Q25: =+Q24+Q23 -> 0 | R25: =IF(Q25=0,0,Q25/Q$42) -> 0 | S25: =+S24+S23 -> 0 | T25: =IF(S25=0,0,S25/S$42) -> 0 | AA25: =IF(OR(B25=0,B25=""),"",B25&IF(COUNTIF(B$11:$B25,B25)>1,COUNTIF(B$11:$B25,B25),"")) -> M149
A26: =AA26 -> M155 | B26: M155 | C26: Other Sales (net) ext. | D26: =VLOOKUP($AA26,Calc_INF_PrevYearEUR!$A$11:$BQ$330,HLOOKUP($C$7,Calc_INF_PrevYearEUR!$E$5:$BQ$6,2,0),0)*IF($C$9="EUR",1,START!$E$18) -> #N/A | E26: =IF(D26=0,0,D26/D$42) -> #N/A | F26: =VLOOKUP($AA26,Calc_INF_FC_EUR!$A$11:$BQ$330,HLOOKUP($C$7,Calc_INF_FC_EUR!$E$5:$BQ$6,2,0),0)*IF($C$9="EUR",1,START!$E$18)+G26 -> #N/A | I26: =SUMIFS(SalesReport!$R:$R,SalesReport!$AF:$AF,$AB26,SalesReport!$A:$A,I$8,SalesReport!$B:$B,BusPlanLocation!$C$7)*IF($C$9="EUR",1,START!$E$18)/1000 -> 0 | J26: =IF(I26=0,0,I26/I$42) -> 0 | K26: =SUMIFS(SalesReport!$R:$R,SalesReport!$AF:$AF,$AB26,SalesReport!$A:$A,K$8,SalesReport!$B:$B,BusPlanLocation!$C$7)*IF($C$9="EUR",1,START!$E$18)/1000 -> 0 | L26: =IF(K26=0,0,K26/K$42) -> 0 | M26: =SUMIFS(SalesReport!$R:$R,SalesReport!$AF:$AF,$AB26,SalesReport!$A:$A,M$8,SalesReport!$B:$B,BusPlanLocation!$C$7)*IF($C$9="EUR",1,START!$E$18)/1000 -> 0 | N26: =IF(M26=0,0,M26/M$42) -> 0 | O26: =SUMIFS(SalesReport!$R:$R,SalesReport!$AF:$AF,$AB26,SalesReport!$A:$A,O$8,SalesReport!$B:$B,BusPlanLocation!$C$7)*IF($C$9="EUR",1,START!$E$18)/1000 -> 0 | P26: =IF(O26=0,0,O26/O$42) -> 0 | Q26: =SUMIFS(SalesReport!$R:$R,SalesReport!$AF:$AF,$AB26,SalesReport!$A:$A,Q$8,SalesReport!$B:$B,BusPlanLocation!$C$7)*IF($C$9="EUR",1,START!$E$18)/1000 -> 0 | R26: =IF(Q26=0,0,Q26/Q$42) -> 0 | S26: =SUMIFS(SalesReport!$R:$R,SalesReport!$AF:$AF,$AB26,SalesReport!$A:$A,S$8,SalesReport!$B:$B,BusPlanLocation!$C$7)*IF($C$9="EUR",1,START!$E$18)/1000 -> 0 | T26: =IF(S26=0,0,S26/S$42) -> 0 | AA26: =IF(OR(B26=0,B26=""),"",B26&IF(COUNTIF(B$11:$B26,B26)>1,COUNTIF(B$11:$B26,B26),"")) -> M155 | AB26: Commission & Servicesext
